I'm sorry, but an uncaught exception occurred.

While running game code:
  File "renpy/common/00start.rpy", line 310, in script call
    call expression "before_main_menu"
  File "game/script.rpy", line 26, in script
    with middissolve
TypeError: __init__() got multiple values for keyword argument 'new_widget'

-- Full Traceback ------------------------------------------------------------

Full traceback:
  File "renpy/common/00start.rpy", line 310, in script call
    call expression "before_main_menu"
  File "game/script.rpy", line 26, in script
    with middissolve
  File "D:\Games\Programmazione giochi\renpy-7.2.2-sdk/renpy/ast.py", line 1437, in execute
    renpy.exports.with_statement(trans, paired)
  File "D:\Games\Programmazione giochi\renpy-7.2.2-sdk/renpy/exports.py", line 1682, in with_statement
    return renpy.game.interface.do_with(trans, paired, clear=clear)
  File "D:\Games\Programmazione giochi\renpy-7.2.2-sdk/renpy/display/core.py", line 2718, in do_with
    clear=clear)
  File "D:\Games\Programmazione giochi\renpy-7.2.2-sdk/renpy/display/core.py", line 3276, in interact
    repeat, rv = self.interact_core(preloads=preloads, trans_pause=trans_pause, pause=pause, pause_start=pause_start, **kwargs)
  File "D:\Games\Programmazione giochi\renpy-7.2.2-sdk/renpy/display/core.py", line 3633, in interact_core
    new_widget=layers_root)
  File "D:\Games\Programmazione giochi\renpy-7.2.2-sdk/renpy/curry.py", line 48, in __call__
    return self.callable(*(self.args + args), **merged_kwargs)
TypeError: __init__() got multiple values for keyword argument 'new_widget'

Windows-10-10.0.19041
Ren'Py 7.4.6.1693
Fantasmi 
Sat Sep 18 14:53:46 2021
